Internal Server Error: /api/pst/
Traceback (most recent call last):
  File "C:\Users\ADMIN\Desktop\PyCharmProjects\django_projects\servak\venv\Lib\site-packages\requests\models.py", line 974, in json
    return complexjson.loads(self.text, **kwargs)
           ^^^^^^^^^^^^^^^^^^^^^^^^^^^^^^^^^^^^^^
  File "C:\Users\ADMIN\AppData\Local\Programs\Python\Python311\Lib\json\__init__.py", line 346, in loads
    return _default_decoder.decode(s)
           ^^^^^^^^^^^^^^^^^^^^^^^^^^
  File "C:\Users\ADMIN\AppData\Local\Programs\Python\Python311\Lib\json\decoder.py", line 337, in decode
    obj, end = self.raw_decode(s, idx=_w(s, 0).end())
               ^^^^^^^^^^^^^^^^^^^^^^^^^^^^^^^^^^^^^^
  File "C:\Users\ADMIN\AppData\Local\Programs\Python\Python311\Lib\json\decoder.py", line 355, in raw_decode
    raise JSONDecodeError("Expecting value", s, err.value) from None
json.decoder.JSONDecodeError: Expecting value: line 1 column 1 (char 0)

During handling of the above exception, another exception occurred:

Traceback (most recent call last):
  File "C:\Users\ADMIN\Desktop\PyCharmProjects\django_projects\servak\venv\Lib\site-packages\django\core\handlers\exception.py", line 55, in inner
    response = get_response(request)
               ^^^^^^^^^^^^^^^^^^^^^
  File "C:\Users\ADMIN\Desktop\PyCharmProjects\django_projects\servak\venv\Lib\site-packages\django\core\handlers\base.py", line 197, in _get_response
    response = wrapped_callback(request, *callback_args, **callback_kwargs)
               ^^^^^^^^^^^^^^^^^^^^^^^^^^^^^^^^^^^^^^^^^^^^^^^^^^^^^^^^^^^^
  File "C:\Users\ADMIN\Desktop\PyCharmProjects\django_projects\servak\posts_service\posts_app\views.py", line 14, in read_posts
    auth_user, uat, urt = get_authenticated_user(request)
                          ^^^^^^^^^^^^^^^^^^^^^^^^^^^^^^^
  File "C:\Users\ADMIN\Desktop\PyCharmProjects\django_projects\servak\posts_service\posts_app\utils.py", line 33, in get_authenticated_user
    data = response_data.json()
           ^^^^^^^^^^^^^^^^^^^^
  File "C:\Users\ADMIN\Desktop\PyCharmProjects\django_projects\servak\venv\Lib\site-packages\requests\models.py", line 978, in json
    raise RequestsJSONDecodeError(e.msg, e.doc, e.pos)
requests.exceptions.JSONDecodeError: Expecting value: line 1 column 1 (char 0)
"GET /api/pst/ HTTP/1.1" 500 149925
Internal Server Error: /api/pst/post/
Traceback (most recent call last):
  File "C:\Users\ADMIN\Desktop\PyCharmProjects\django_projects\servak\venv\Lib\site-packages\requests\models.py", line 974, in json
    return complexjson.loads(self.text, **kwargs)
           ^^^^^^^^^^^^^^^^^^^^^^^^^^^^^^^^^^^^^^
  File "C:\Users\ADMIN\AppData\Local\Programs\Python\Python311\Lib\json\__init__.py", line 346, in loads
    return _default_decoder.decode(s)
           ^^^^^^^^^^^^^^^^^^^^^^^^^^
  File "C:\Users\ADMIN\AppData\Local\Programs\Python\Python311\Lib\json\decoder.py", line 337, in decode
    obj, end = self.raw_decode(s, idx=_w(s, 0).end())
               ^^^^^^^^^^^^^^^^^^^^^^^^^^^^^^^^^^^^^^
  File "C:\Users\ADMIN\AppData\Local\Programs\Python\Python311\Lib\json\decoder.py", line 355, in raw_decode
    raise JSONDecodeError("Expecting value", s, err.value) from None
json.decoder.JSONDecodeError: Expecting value: line 1 column 1 (char 0)

During handling of the above exception, another exception occurred:

Traceback (most recent call last):
  File "C:\Users\ADMIN\Desktop\PyCharmProjects\django_projects\servak\venv\Lib\site-packages\django\core\handlers\exception.py", line 55, in inner
    response = get_response(request)
               ^^^^^^^^^^^^^^^^^^^^^
  File "C:\Users\ADMIN\Desktop\PyCharmProjects\django_projects\servak\venv\Lib\site-packages\django\core\handlers\base.py", line 197, in _get_response
    response = wrapped_callback(request, *callback_args, **callback_kwargs)
               ^^^^^^^^^^^^^^^^^^^^^^^^^^^^^^^^^^^^^^^^^^^^^^^^^^^^^^^^^^^^
  File "C:\Users\ADMIN\Desktop\PyCharmProjects\django_projects\servak\posts_service\posts_app\views.py", line 67, in create_post
    auth_user, uat, urt = get_authenticated_user(request)
                          ^^^^^^^^^^^^^^^^^^^^^^^^^^^^^^^
  File "C:\Users\ADMIN\Desktop\PyCharmProjects\django_projects\servak\posts_service\posts_app\utils.py", line 33, in get_authenticated_user
    data = response_data.json()
           ^^^^^^^^^^^^^^^^^^^^
  File "C:\Users\ADMIN\Desktop\PyCharmProjects\django_projects\servak\venv\Lib\site-packages\requests\models.py", line 978, in json
    raise RequestsJSONDecodeError(e.msg, e.doc, e.pos)
requests.exceptions.JSONDecodeError: Expecting value: line 1 column 1 (char 0)
"POST /api/pst/post/ HTTP/1.1" 500 151779
Internal Server Error: /api/pst/
Traceback (most recent call last):
  File "C:\Users\ADMIN\Desktop\PyCharmProjects\django_projects\servak\venv\Lib\site-packages\requests\models.py", line 974, in json
    return complexjson.loads(self.text, **kwargs)
           ^^^^^^^^^^^^^^^^^^^^^^^^^^^^^^^^^^^^^^
  File "C:\Users\ADMIN\AppData\Local\Programs\Python\Python311\Lib\json\__init__.py", line 346, in loads
    return _default_decoder.decode(s)
           ^^^^^^^^^^^^^^^^^^^^^^^^^^
  File "C:\Users\ADMIN\AppData\Local\Programs\Python\Python311\Lib\json\decoder.py", line 337, in decode
    obj, end = self.raw_decode(s, idx=_w(s, 0).end())
               ^^^^^^^^^^^^^^^^^^^^^^^^^^^^^^^^^^^^^^
  File "C:\Users\ADMIN\AppData\Local\Programs\Python\Python311\Lib\json\decoder.py", line 355, in raw_decode
    raise JSONDecodeError("Expecting value", s, err.value) from None
json.decoder.JSONDecodeError: Expecting value: line 1 column 1 (char 0)

During handling of the above exception, another exception occurred:

Traceback (most recent call last):
  File "C:\Users\ADMIN\Desktop\PyCharmProjects\django_projects\servak\venv\Lib\site-packages\django\core\handlers\exception.py", line 55, in inner
    response = get_response(request)
               ^^^^^^^^^^^^^^^^^^^^^
  File "C:\Users\ADMIN\Desktop\PyCharmProjects\django_projects\servak\venv\Lib\site-packages\django\core\handlers\base.py", line 197, in _get_response
    response = wrapped_callback(request, *callback_args, **callback_kwargs)
               ^^^^^^^^^^^^^^^^^^^^^^^^^^^^^^^^^^^^^^^^^^^^^^^^^^^^^^^^^^^^
  File "C:\Users\ADMIN\Desktop\PyCharmProjects\django_projects\servak\posts_service\posts_app\views.py", line 14, in read_posts
    auth_user, uat, urt = get_authenticated_user(request)
                          ^^^^^^^^^^^^^^^^^^^^^^^^^^^^^^^
  File "C:\Users\ADMIN\Desktop\PyCharmProjects\django_projects\servak\posts_service\posts_app\utils.py", line 33, in get_authenticated_user
    data = response_data.json()
           ^^^^^^^^^^^^^^^^^^^^
  File "C:\Users\ADMIN\Desktop\PyCharmProjects\django_projects\servak\venv\Lib\site-packages\requests\models.py", line 978, in json
    raise RequestsJSONDecodeError(e.msg, e.doc, e.pos)
requests.exceptions.JSONDecodeError: Expecting value: line 1 column 1 (char 0)
"GET /api/pst/ HTTP/1.1" 500 150089
Internal Server Error: /api/pst/
Traceback (most recent call last):
  File "C:\Users\ADMIN\Desktop\PyCharmProjects\django_projects\servak\venv\Lib\site-packages\requests\models.py", line 974, in json
    return complexjson.loads(self.text, **kwargs)
           ^^^^^^^^^^^^^^^^^^^^^^^^^^^^^^^^^^^^^^
  File "C:\Users\ADMIN\AppData\Local\Programs\Python\Python311\Lib\json\__init__.py", line 346, in loads
    return _default_decoder.decode(s)
           ^^^^^^^^^^^^^^^^^^^^^^^^^^
  File "C:\Users\ADMIN\AppData\Local\Programs\Python\Python311\Lib\json\decoder.py", line 337, in decode
    obj, end = self.raw_decode(s, idx=_w(s, 0).end())
               ^^^^^^^^^^^^^^^^^^^^^^^^^^^^^^^^^^^^^^
  File "C:\Users\ADMIN\AppData\Local\Programs\Python\Python311\Lib\json\decoder.py", line 355, in raw_decode
    raise JSONDecodeError("Expecting value", s, err.value) from None
json.decoder.JSONDecodeError: Expecting value: line 1 column 1 (char 0)

During handling of the above exception, another exception occurred:

Traceback (most recent call last):
  File "C:\Users\ADMIN\Desktop\PyCharmProjects\django_projects\servak\venv\Lib\site-packages\django\core\handlers\exception.py", line 55, in inner
    response = get_response(request)
               ^^^^^^^^^^^^^^^^^^^^^
  File "C:\Users\ADMIN\Desktop\PyCharmProjects\django_projects\servak\venv\Lib\site-packages\django\core\handlers\base.py", line 197, in _get_response
    response = wrapped_callback(request, *callback_args, **callback_kwargs)
               ^^^^^^^^^^^^^^^^^^^^^^^^^^^^^^^^^^^^^^^^^^^^^^^^^^^^^^^^^^^^
  File "C:\Users\ADMIN\Desktop\PyCharmProjects\django_projects\servak\posts_service\posts_app\views.py", line 14, in read_posts
    auth_user, uat, urt = get_authenticated_user(request)
                          ^^^^^^^^^^^^^^^^^^^^^^^^^^^^^^^
  File "C:\Users\ADMIN\Desktop\PyCharmProjects\django_projects\servak\posts_service\posts_app\utils.py", line 33, in get_authenticated_user
    data = response_data.json()
           ^^^^^^^^^^^^^^^^^^^^
  File "C:\Users\ADMIN\Desktop\PyCharmProjects\django_projects\servak\venv\Lib\site-packages\requests\models.py", line 978, in json
    raise RequestsJSONDecodeError(e.msg, e.doc, e.pos)
requests.exceptions.JSONDecodeError: Expecting value: line 1 column 1 (char 0)
"GET /api/pst/ HTTP/1.1" 500 149925
Internal Server Error: /api/pst/
Traceback (most recent call last):
  File "C:\Users\ADMIN\Desktop\PyCharmProjects\django_projects\servak\venv\Lib\site-packages\requests\models.py", line 974, in json
    return complexjson.loads(self.text, **kwargs)
           ^^^^^^^^^^^^^^^^^^^^^^^^^^^^^^^^^^^^^^
  File "C:\Users\ADMIN\AppData\Local\Programs\Python\Python311\Lib\json\__init__.py", line 346, in loads
    return _default_decoder.decode(s)
           ^^^^^^^^^^^^^^^^^^^^^^^^^^
  File "C:\Users\ADMIN\AppData\Local\Programs\Python\Python311\Lib\json\decoder.py", line 337, in decode
    obj, end = self.raw_decode(s, idx=_w(s, 0).end())
               ^^^^^^^^^^^^^^^^^^^^^^^^^^^^^^^^^^^^^^
  File "C:\Users\ADMIN\AppData\Local\Programs\Python\Python311\Lib\json\decoder.py", line 355, in raw_decode
    raise JSONDecodeError("Expecting value", s, err.value) from None
json.decoder.JSONDecodeError: Expecting value: line 1 column 1 (char 0)

During handling of the above exception, another exception occurred:

Traceback (most recent call last):
  File "C:\Users\ADMIN\Desktop\PyCharmProjects\django_projects\servak\venv\Lib\site-packages\django\core\handlers\exception.py", line 55, in inner
    response = get_response(request)
               ^^^^^^^^^^^^^^^^^^^^^
  File "C:\Users\ADMIN\Desktop\PyCharmProjects\django_projects\servak\venv\Lib\site-packages\django\core\handlers\base.py", line 197, in _get_response
    response = wrapped_callback(request, *callback_args, **callback_kwargs)
               ^^^^^^^^^^^^^^^^^^^^^^^^^^^^^^^^^^^^^^^^^^^^^^^^^^^^^^^^^^^^
  File "C:\Users\ADMIN\Desktop\PyCharmProjects\django_projects\servak\posts_service\posts_app\views.py", line 14, in read_posts
    auth_user, uat, urt = get_authenticated_user(request)
                          ^^^^^^^^^^^^^^^^^^^^^^^^^^^^^^^
  File "C:\Users\ADMIN\Desktop\PyCharmProjects\django_projects\servak\posts_service\posts_app\utils.py", line 33, in get_authenticated_user
    data = response_data.json()
           ^^^^^^^^^^^^^^^^^^^^
  File "C:\Users\ADMIN\Desktop\PyCharmProjects\django_projects\servak\venv\Lib\site-packages\requests\models.py", line 978, in json
    raise RequestsJSONDecodeError(e.msg, e.doc, e.pos)
requests.exceptions.JSONDecodeError: Expecting value: line 1 column 1 (char 0)
"GET /api/pst/ HTTP/1.1" 500 149794
DEBUG 2024-11-06 13:47:36,149 async_kafka_producer Message sent: User: 1 created post: 47
DEBUG 2024-11-06 14:38:48,952 async_kafka_producer Message sent: User: 1 created post: 48
DEBUG 2024-11-06 14:40:39,788 async_kafka_producer Message sent: User: 1 created post: 49
DEBUG 2024-11-06 14:45:22,527 async_kafka_producer Message sent: User: 1 created post: 50
DEBUG 2024-11-06 15:08:04,732 async_kafka_producer Message sent: User: 1 created post: 51
DEBUG 2024-11-06 18:56:23,020 async_kafka_producer Message sent: User: 3 created post: 55
DEBUG 2024-11-06 18:58:40,272 async_kafka_producer Message sent: User: 3 created post: 56
DEBUG 2024-11-06 19:00:42,311 async_kafka_producer Message sent: User: 3 created post: 57
DEBUG 2024-11-06 19:03:19,991 async_kafka_producer Message sent: User: 3 created post: 58
DEBUG 2024-11-06 19:05:15,718 async_kafka_producer Message sent: User: 3 created post: 59
DEBUG 2024-11-06 19:10:29,556 async_kafka_producer Message sent: User: 3 created post: 60
DEBUG 2024-11-06 19:15:59,960 async_kafka_producer Message sent: User: 3 created post: 61
DEBUG 2024-11-06 19:17:30,776 async_kafka_producer Message sent: User: 3 created post: 62
DEBUG 2024-11-06 19:20:14,479 async_kafka_producer Message sent: User: 3 created post: 63
DEBUG 2024-11-06 19:29:02,474 async_kafka_producer Message sent: User: 3 created post: 64
DEBUG 2024-11-06 19:32:07,032 async_kafka_producer Message sent: User: 3 created post: 65
DEBUG 2024-11-06 19:42:23,520 async_kafka_producer Message sent: User: 3 created post: 66
DEBUG 2024-11-06 19:44:17,360 async_kafka_producer Message sent: User: 3 created post: 67
DEBUG 2024-11-06 19:51:19,269 async_kafka_producer Message sent: User: 3 created post: 68
DEBUG 2024-11-06 19:58:53,234 async_kafka_producer Message sent: User: 3 created post: 69
DEBUG 2024-11-06 20:04:42,710 async_kafka_producer Message sent: User: 3 created post: 70
DEBUG 2024-11-06 20:09:42,052 async_kafka_producer Message sent: User: 3 created post: 71
DEBUG 2024-11-06 20:14:13,819 async_kafka_producer Message sent: User: 3 created post: 72
DEBUG 2024-11-06 20:24:21,596 async_kafka_producer Message sent: User: 3 created post: 73
DEBUG 2024-11-06 20:38:48,654 async_kafka_producer Message sent: User: 3 created post: 74
DEBUG 2024-11-06 20:40:01,180 async_kafka_producer Message sent: User: 3 created post: 75
DEBUG 2024-11-06 20:40:40,732 async_kafka_producer Message sent: User: 3 created post: 76
DEBUG 2024-11-06 20:41:19,523 async_kafka_producer Message sent: User: 3 created post: 77
DEBUG 2024-11-06 20:41:50,205 async_kafka_producer Message sent: User: 3 created post: 78
DEBUG 2024-11-07 09:33:23,210 async_kafka_producer Message sent: User: 3 created post: 81
